tests/complex_49.in
40
o
13 B 101 ADX 261 866
9 B 102 AIZN 1467 784
26 S 103 BERY 1565 768
31 C 401
13 S 105 ALIT 1060 727
24 S 106 ADC 1936 506
29 S 107 AGL 687 343
24 C 817
31 C 460
25 C 562
21 B 111 BFZ 1537 792
34 B 112 AAC 710 112
34 B 113 AYX 1527 987
26 C 118
25 C 897
4 B 116 AME 563 263
30 S 117 BLUA 1833 236
25 C 979
1 S 119 AVYA 718 874
23 S 120 ATR 650 909
31 S 121 ANF 293 771
12 C 927
12 S 123 BBY 1591 392
38 B 124 AI 938 506
14 C 159
13 C 460
0 C 942
0 B 128 AFB 1252 251
37 C 462
20 B 130 ALX 1503 202
13 S 131 ALCC 1176 257
20 S 132 AAIC 478 626
2 B 133 AIF 792 577
18 B 134 AZUL 1357 578
19 S 135 B 1511 522
22 C 777
19 C 163
31 S 138 AXAC 389 381
17 B 139 AEG 173 404
0 S 140 ALL^G 1738 284
32 B 141 ATR 679 353
38 S 142 ASX 327 504
2 B 143 ALX 296 827
33 B 144 ARES 1106 567
10 S 145 BKDT 307 547
37 B 146 AWF 278 619
21 B 147 BFS^D 1786 278
25 C 903
31 B 149 ASAI 522 38
19 B 150 BERY 1108 497
18 B 151 BACA 711 860
12 S 152 AWK 236 767
30 C 1014
38 S 154 A 930 575
13 C 752
0 B 156 AL 515 498
8 C 827
28 B 158 ATH^D 741 670
33 C 518
38 S 160 AOS 639 809
11 B 161 AFTR 863 826
4 S 162 AM 1457 824
39 B 163 A 1679 489
31 S 164 ALLE 1462 569
32 C 170
33 S 166 AA 1559 722
2 C 313
32 C 360
36 S 169 ATH^C 1384 573
39 C 516
12 S 171 AMN 314 212
5 C 295
1 B 173 ALCC 231 611
1 C 854
22 C 169
26 B 176 BBVA 1423 599
16 S 177 ABT 1891 371
38 B 178 AAIC 1884 775
31 C 1060
21 S 180 BGS 1401 835
28 C 1085
5 S 182 BC^A 1119 658
22 B 183 ATKR 364 350
32 C 147
11 C 910
23 S 186 ALL^I 1846 393
0 C 513
16 B 188 AXL 1552 590
36 C 565
38 S 190 AMH^H 1358 374
32 C 231
26 C 622
25 S 193 AFTR 1509 915
20 S 194 AGCO 448 721
11 S 195 BFAM 716 271
31 B 196 AZEK 964 236
11 C 788
28 B 198 AUB 1800 131
32 S 199 BF/B 1457 311
1 C 924
37 B 201 BALL 294 571
5 B 202 ADC^A 675 719
21 C 138
18 C 441
15 S 205 AFTR 935 320
37 B 206 ACA 555 270
15 C 428
23 C 1107
11 C 492
16 B 210 ABB 1702 358
30 B 211 AVB 869 154
19 S 212 BKSY 616 102
7 C 402
31 B 214 BLW 1755 943
4 B 215 ATCO^D 1397 231
13 S 216 ASGN 587 563
39 C 496
1 C 355
0 B 219 BLCO 1447 65
0 S 220 BGB 1357 614
37 B 221 AQNB 982 774
15 B 222 AXL 1174 288
9 S 223 AEM 1259 658
14 S 224 ASC 697 265
27 C 215
38 C 1125
26 C 587
28 S 228 BHVN 177 827
6 B 229 BBDC 257 82
21 B 230 BABA 1616 446
23 S 231 AUD 438 760
34 B 232 AVNS 734 144
22 C 703
2 B 234 BLDR 1092 61
28 S 235 BIO/B 1811 883
15 B 236 APH 563 38
0 S 237 BAM 404 601
21 S 238 AKA 754 355
3 C 968
16 B 240 ACN 1108 705
22 C 125
34 C 107
17 S 243 ALL^I 259 353
10 S 244 AVTR 1085 372
2 B 245 BKU 1046 178
38 B 246 ABC 1922 114
17 S 247 ATTO 1274 797
15 B 248 AG 175 942
37 S 249 BB 1174 724
6 B 250 ASX 1783 98
12 B 251 AROC 1025 645
1 C 1180
7 C 200
5 S 254 BGY 680 15
10 S 255 AWR 1231 825
13 S 256 ARW 1361 778
3 C 685
31 S 258 APCA 1759 540
17 B 259 BF/A 533 421
10 C 916
15 C 989
7 B 262 BF/B 695 961
14 S 263 BMI 966 339
34 B 264 BBAR 703 784
28 C 1044
16 B 266 ALX 797 319
7 B 267 AWR 2000 237
1 S 268 BMI 1525 564
37 B 269 AXL 690 932
13 S 270 BME 1787 421
9 B 271 APCA 776 578
10 B 272 BGT 1111 651
15 B 273 AB 210 733
25 S 274 BBDO 1313 59
34 B 275 AHL^E 1720 112
36 S 276 ASB 1351 373
8 B 277 BFAC 600 870
33 C 825
7 C 339
29 B 280 AIRC 1025 953
34 C 159
16 B 282 AMG 645 86
39 C 1198
27 B 284 BME 1810 604
20 C 844
8 C 1032
27 S 287 ALLG 167 526
33 C 1070
30 B 289 ACN 1867 398
19 S 290 AFL 276 544
21 S 291 ADT 1370 325
10 C 345
33 S 293 AHT^I 1288 758
18 C 447
8 S 295 AIV 1622 482
30 B 296 AXL 617 529
25 C 1065
26 C 130
6 B 299 AHH^A 1935 279
16 S 300 BEN 1660 851
36 C 697
26 B 302 AZEK 469 704
11 S 303 AEL 1035 331
26 B 304 ANET 1937 275
15 S 305 BDXB 1675 552
30 C 900
8 B 307 ALX 1259 886
12 B 308 BHR 1788 714
30 B 309 BCO 427 791
5 B 310 AZO 1901 591
3 C 168
10 S 312 AG 1678 676
11 C 303
29 S 314 BKI 1920 217
12 C 162
2 B 316 BFAM 1150 577
8 S 317 BLX 1128 738
8 B 318 BFS^E 637 639
14 C 528
12 B 320 AMAM 1863 787
14 C 1035
24 B 322 ASA 1640 936
7 S 323 BIP^A 551 408
0 B 324 BGH 555 98
4 B 325 AJXA 1489 252
36 S 326 AMH 358 645
11 S 327 ALL^G 108 835
24 S 328 AIO 447 764
10 S 329 AEM 1590 834
14 B 330 BML^H 1068 171
24 B 331 ARNC 348 38
2 B 332 ATH^C 362 886
14 S 333 ARI 1006 271
22 S 334 BGT 296 811
30 C 996
19 S 336 ACA 1978 925
35 S 337 BHE 452 641
0 S 338 AEL 703 680
30 C 971
32 B 340 BAC 1436 750
4 B 341 ATCO^H 1541 409
30 C 873
5 B 343 BGS 1579 512
4 C 785
36 C 900
8 S 346 BAC^O 234 518
28 C 915
12 S 348 BLCO 1243 425
22 S 349 AMBP 307 876
26 B 350 AL^A 1631 289
30 B 351 AIZ 1230 290
15 S 352 AAP 923 473
26 C 715
23 C 293
34 C 227
28 C 101
39 B 357 AOD 612 603
13 S 358 AGS 922 927
31 S 359 ATEK 1835 880
23 S 360 BKDT 867 362
5 B 361 ABB 1160 38
35 S 362 ARR^C 709 707
39 C 218
24 C 803
26 C 626
25 S 366 ATTO 1427 947
30 B 367 BJ 919 535
8 S 368 ALL^H 1734 490
39 S 369 AWP 1900 658
20 B 370 AR 778 734
2 C 458
5 S 372 ARCH 1758 260
23 B 373 ATCO^H 1790 456
21 S 374 BFS^D 1583 186
24 S 375 BERY 1166 771
18 S 376 AGI 249 175
6 C 1180
31 S 378 AIC 1686 657
19 C 1262
31 B 380 AZEK 468 571
36 B 381 BIPI 1762 437
10 S 382 BF/B 1436 157
36 C 342
10 S 384 AVY 1535 86
34 S 385 ASX 1330 396
18 C 742
37 B 387 BCC 835 331
12 B 388 BGSF 1173 572
17 B 389 ABR 1869 733
14 C 376
24 C 1120
30 B 392 BGSX 710 261
3 S 393 BFK 1456 998
18 B 394 BLW 1943 137
7 C 841
12 S 396 AUD 1915 666
26 C 913
3 C 136
34 S 399 BC^A 826 430
34 S 400 BBAI 1085 571
27 S 401 ACHR 1066 166
25 S 402 AXL 341 217
4 C 1287
8 C 750
19 S 405 ALTG 323 688
16 C 1074
8 C 456
31 S 408 ALEX 593 337
14 S 409 ATUS 490 104
39 C 807
10 S 411 AIZN 508 62
1 B 412 BCX 160 986
5 C 939
23 S 414 AMX 1766 690
5 B 415 BC^C 619 327
28 C 996
30 C 1361
20 B 418 BCSF 1422 206
31 S 419 APTV 1233 449
34 C 1379
0 S 421 AUB 101 539
14 C 290
24 B 423 BDX 1206 446
26 B 424 BBAR 1439 57
29 S 425 BGX 987 403
23 S 426 ABG 1471 585
9 S 427 ATH^E 1721 211
6 C 1097
31 S 429 AFGD 882 668
5 C 294
16 C 653
5 C 661
10 S 433 AGL 900 810
19 C 738
28 S 435 AMCR 1041 697
38 S 436 AGS 1492 246
13 S 437 AKO/A 1864 829
8 C 1347
23 C 1339
35 B 440 BBLN 188 505
26 S 441 AOD 1157 37
14 S 442 BHE 1081 404
27 B 443 ASGI 1246 868
13 S 444 BBU 625 876
15 C 1364
29 S 446 AFGB 850 753
32 S 447 BLK 1757 876
8 S 448 BHK 1184 436
18 S 449 ABC 832 310
20 B 450 AHT 1326 313
21 C 207
33 S 452 BEPH 1945 801
4 S 453 AVD 1784 969
31 B 454 BIP 1411 463
36 C 454
13 S 456 BCSF 790 60
6 C 546
2 C 1256
24 S 459 BB 688 249
28 B 460 BCSF 1809 605
25 C 1310
18 B 462 ATIP 1676 461
21 B 463 BML^G 1217 657
17 S 464 AUB 786 433
3 B 465 ALLG 848 346
1 B 466 AQNA 586 690
15 S 467 BIG 644 69
10 B 468 BJ 530 912
34 S 469 ASG 1240 463
8 S 470 AVYA 785 269
8 C 563
8 B 472 ADC^A 1765 422
17 S 473 AMBC 729 264
28 C 636
38 S 475 ASIX 1089 83
28 S 476 APE 155 975
20 S 477 ATAQ 944 288
9 C 372
11 B 479 AXS 394 699
31 B 480 AHT^G 1367 361
22 S 481 ASAN 596 165
16 B 482 BFS^E 1946 158
9 S 483 ASB^F 250 96
10 C 459
36 B 485 AUB 1446 615
37 C 918
29 C 1004
23 B 488 AXTA 991 846
17 C 975
15 C 403
13 B 491 BANC 470 746
16 S 492 BGH 1825 629
7 B 493 ALCC 394 580
37 S 494 BKU 511 268
8 S 495 ACR^C 1925 668
30 S 496 AQUA 726 608
7 B 497 ALV 411 843
7 S 498 AHH^A 204 251
15 C 810
39 C 1100
2 C 333
36 S 502 AYX 1478 788
18 B 503 ARIS 1547 141
31 C 488
30 B 505 BHR 1149 40
31 B 506 AROC 1880 784
11 S 507 AMRX 1923 562
24 C 319
3 C 1282
23 S 510 ADC 136 603
36 C 434
8 S 512 AHL^D 101 945
7 S 513 AMRC 275 332
16 S 514 ANF 927 86
20 B 515 ADM 130 756
19 B 516 AAIC^C 746 776
24 B 517 AFL 1099 68
23 C 766
28 S 519 BMA 1998 810
21 S 520 BLX 864 891
7 C 1169
26 C 521
14 S 523 ABR^F 1422 866
1 S 524 ACR^D 341 923
30 B 525 BCSF 1569 671
13 B 526 BMAC 1339 916
38 S 527 AMRX 1100 673
24 S 528 AESC 597 501
33 B 529 AHT 1682 158
16 B 530 BBU 850 425
34 S 531 BGS 1384 225
35 C 616
36 S 533 AOS 1466 91
22 B 534 AAM^B 373 532
0 C 187
37 C 904
3 S 537 AHT 1153 353
36 C 649
12 B 539 AJX 1595 283
17 C 1244
25 B 541 BLDR 586 298
32 B 542 AVAL 1691 738
18 C 705
12 C 188
33 B 545 ACRE 1320 108
38 C 158
25 B 547 ARW 114 475
27 B 548 BDJ 169 396
24 B 549 AGM^C 374 898
11 S 550 APTV 1590 644
37 S 551 ATR 1056 703
16 B 552 AMC 1620 688
5 C 273
8 S 554 AGAC 1107 853
