tests/complex_5.in
40
o
20 B 100 BBW 1699 828
39 S 101 APLE 1296 855
11 B 102 ARLO 700 642
24 B 103 ACHR 1824 907
36 S 104 ATIP 1107 201
26 S 105 AIT 1477 14
20 B 106 ACEL 1529 223
20 B 107 AZZ 1610 327
13 B 108 AIZ 1841 575
31 S 109 BCC 1735 682
16 B 110 ACCO 655 583
15 B 111 AGM^C 1332 655
30 S 112 BEKE 491 81
14 S 113 BBW 1691 55
8 B 114 BLK 756 335
23 B 115 ASG 524 885
15 B 116 BC^B 918 495
37 B 117 AZUL 861 62
34 B 118 AFT 1441 438
11 S 119 ATKR 535 880
5 S 120 ASAN 463 677
39 S 121 BAC^O 1647 820
29 B 122 APG 667 231
4 S 123 BBW 1369 276
13 B 124 BLX 1660 544
2 S 125 ANET 930 352
15 S 126 BGB 622 612
24 S 127 BLDR 897 176
3 S 128 BMEZ 533 379
1 B 129 APRN 1773 454
11 S 130 BIO 186 781
4 S 131 ARGO 1981 607
2 B 132 ARIS 1974 206
6 B 133 BBD 190 520
6 S 134 AVYA 172 751
13 S 135 ABR 1274 339
25 B 136 ALSN 1520 177
16 B 137 ALG 1465 391
32 S 138 ASAN 1567 469
32 B 139 ATI 152 90
7 B 140 ATTO 1365 682
11 B 141 AWF 126 884
29 B 142 ACM 493 897
22 B 143 AHT^I 1338 532
37 B 144 APH 481 999
38 S 145 ACI 762 409
13 S 146 AIF 1554 229
22 B 147 BEKE 1745 624
11 B 148 ARW 1779 321
0 B 149 AFL 839 423
15 B 150 ALL^B 606 779
34 S 151 BDXB 1211 383
38 B 152 AQUA 1614 409
23 S 153 BAC^L 1391 440
1 B 154 ADT 1260 284
30 B 155 AIRC 307 793
33 S 156 AVNT 394 479
29 S 157 AAIN 272 656
17 B 158 ALTG 441 883
6 B 159 BCSF 502 986
35 B 160 AQNU 736 669
21 S 161 APLE 190 183
22 S 162 AMCR 1299 160
23 B 163 BHR^D 1401 932
26 S 164 BKE 201 74
27 B 165 BHIL 778 377
3 S 166 AMPY 1514 647
36 B 167 ADM 1040 433
14 B 168 AGRO 386 119
37 B 169 AAP 1846 512
27 B 170 APGB 369 384
31 B 171 ARNC 186 636
23 S 172 ACR^C 630 628
3 S 173 AGM^G 1792 440
1 S 174 AKR 127 642
2 B 175 AMC 614 732
24 B 176 BML^J 1677 860
1 B 177 ARDC 1474 386
31 S 178 A 1962 248
20 B 179 BDC 1556 699
26 B 180 AAIN 1001 530
25 B 181 AIF 286 10
2 S 182 AAIC^C 252 680
15 B 183 AQNB 843 846
3 S 184 BBWI 1986 280
9 S 185 BC 314 125
18 S 186 ANET 1121 17
12 B 187 BILL 806 693
32 S 188 AXS^E 1880 304
21 S 189 ALV 1977 638
16 B 190 AVB 1195 569
21 S 191 AHL^C 1336 545
3 S 192 AWF 1324 130
2 B 193 AXTA 422 317
30 S 194 BGB 134 300
9 B 195 ASX 488 577
16 B 196 ACM 558 194
25 B 197 ATCO^I 1302 505
15 S 198 AHT^D 1232 458
28 B 199 ALL^G 965 391
36 B 200 BME 303 327
28 S 201 ALK 906 916
11 B 202 BAK 579 694
39 S 203 ALTG 1149 983
0 B 204 ARES 176 818
39 B 205 BGB 1830 660
22 B 206 BLUA 1782 650
9 S 207 BALL 520 124
32 B 208 AGM 293 748
36 B 209 APRN 497 96
6 S 210 BAC^E 305 939
34 S 211 AEL^A 1268 184
20 S 212 APD 1486 512
26 B 213 AEVA 312 213
14 S 214 AGO 681 200
23 B 215 BABA 1093 404
8 B 216 ABB 810 992
24 B 217 AGM^G 357 67
11 S 218 ACN 911 224
27 B 219 AZZ 661 345
31 S 220 AFTR 290 449
32 S 221 BBAI 1085 387
26 B 222 BB 1412 362
29 S 223 BCH 746 145
13 S 224 APD 1212 340
13 B 225 BCC 277 11
31 B 226 BEPI 1902 403
27 S 227 BGSF 1280 661
36 S 228 BBAI 633 418
36 B 229 ARCO 1558 918
31 B 230 BLX 771 941
35 B 231 AIZ 1368 166
2 B 232 A 1498 41
7 S 233 ALG 1945 788
30 S 234 AUB^A 604 869
8 B 235 AOD 996 556
16 S 236 BEST 1452 356
6 S 237 ALL^B 1416 641
11 S 238 AVTR 1515 268
7 S 239 BGSF 772 124
13 B 240 AVNS 1719 421
11 B 241 ALG 474 523
8 B 242 BCS 841 648
13 S 243 BGR 818 182
7 B 244 ALSN 1919 351
17 B 245 AGS 770 523
19 B 246 AXP 1726 613
10 S 247 AEVA 1740 880
24 S 248 AEL^B 521 352
39 B 249 ALEX 1427 344
31 B 250 BBDC 912 457
30 S 251 BEKE 131 528
16 S 252 BEN 1073 517
14 S 253 BHLB 1237 839
13 S 254 APTV 1637 628
18 S 255 ACEL 1613 483
10 S 256 AMAM 139 719
14 B 257 BIPC 423 457
15 S 258 BFAM 535 365
5 B 259 AMX 346 78
32 B 260 AQNU 718 642
11 B 261 AEE 1628 47
16 S 262 BCAT 1728 112
26 B 263 AUD 793 174
35 S 264 AXS^E 1061 221
34 B 265 ASGN 1174 151
28 B 266 ALTG 504 411
30 S 267 AZZ 210 91
29 S 268 BEPH 790 650
28 B 269 BMA 856 744
3 B 270 AMBP 125 919
21 S 271 ADNT 334 447
37 B 272 AMBC 695 875
2 S 273 BIPI 1615 320
3 S 274 AU 813 482
14 S 275 AIN 1729 772
5 S 276 BHV 1194 856
5 S 277 ABEV 209 974
25 S 278 AGL 1454 410
14 S 279 ASPN 1139 736
5 S 280 ATH^D 528 751
26 S 281 BAC 285 407
15 S 282 ARR^C 1062 93
18 B 283 BHP 879 741
16 S 284 AEL^B 717 981
7 S 285 AOD 1515 42
25 B 286 ACP 229 391
18 S 287 AWI 226 177
35 B 288 BMAC 464 225
24 S 289 AGRO 1053 646
22 B 290 AXAC 200 173
33 B 291 AJXA 1505 907
20 S 292 ALL^I 1495 76
36 B 293 ASAI 1943 690
34 B 294 ACHR 1792 785
18 B 295 AMP 1891 697
17 B 296 BAK 893 482
5 S 297 BAC 1740 619
17 B 298 ARLO 750 725
21 S 299 BAC^Q 383 840
33 B 300 ASGN 1701 997
14 B 301 ATKR 1215 862
14 B 302 AEL^A 1454 546
33 B 303 AHT^F 1241 887
0 S 304 AMX 1340 217
30 S 305 ATCO^I 184 461
25 B 306 ABB 1489 713
19 S 307 AON 717 638
29 S 308 AER 803 530
13 S 309 ALL^H 721 527
30 S 310 ASB^F 921 34
16 S 311 AL 725 553
9 B 312 AVNS 888 711
30 B 313 ARCO 1863 549
16 S 314 AGAC 304 618
8 B 315 ACDI 1850 858
3 S 316 AQNA 500 609
1 S 317 BKN 106 515
17 B 318 BGT 1608 806
26 B 319 AEL^B 210 101
32 S 320 BDX 1264 799
9 B 321 BC 537 941
34 B 322 BBDO 1865 305
28 S 323 AR 1854 860
24 B 324 AOMR 650 861
37 B 325 BHLB 1366 375
4 B 326 BIG 1082 290
2 S 327 AON 317 836
20 S 328 BB 314 33
4 S 329 ANF 656 677
0 S 330 ASX 147 411
11 S 331 AGO 1133 755
6 B 332 ATH^E 1412 459
2 B 333 ALLG 539 632
29 B 334 A 607 96
24 S 335 BDN 1900 543
18 S 336 ALV 544 742
3 B 337 AMBC 1006 153
7 B 338 ADC^A 362 361
27 S 339 AME 1628 652
14 S 340 AVY 1434 491
3 B 341 ARNC 356 164
29 S 342 ACEL 336 687
21 B 343 AORT 1062 332
2 B 344 AMBP 1387 243
34 B 345 AER 1542 724
15 S 346 ARIS 119 603
8 B 347 BHC 941 801
1 B 348 BCSF 591 255
36 B 349 A 1098 47
14 S 350 AOD 1040 912
14 S 351 BHE 1120 990
38 B 352 BIO 256 993
15 S 353 BACA 1095 364
10 S 354 ALLG 1677 513
6 B 355 ARGD 1684 274
26 B 356 AGO 202 251
28 B 357 BALL 875 96
22 S 358 AER 1195 186
27 S 359 BC^A 701 539
26 B 360 AOD 1975 474
8 S 361 BEP 1054 448
32 B 362 AGM^E 701 534
37 S 363 BLE 1924 703
32 B 364 AEM 822 70
31 S 365 ASG 1316 546
9 B 366 AAP 1610 860
18 S 367 ADC^A 327 131
2 B 368 BFZ 956 408
22 S 369 AVK 995 880
9 B 370 APTV 1040 161
29 B 371 ALL^H 1226 206
6 B 372 ABR^F 1245 714
2 B 373 ATCO^H 1346 153
3 S 374 BDJ 400 968
21 B 375 ALV 1780 928
11 S 376 ADCT 243 663
37 S 377 AIG^A 1793 614
33 S 378 BKT 1370 717
33 S 379 BLW 368 637
21 B 380 AMTD 1034 290
16 S 381 BDX 1991 381
23 S 382 ATCO^I 823 629
10 S 383 BLCO 179 875
34 B 384 BAC^S 273 862
3 S 385 AXP 981 755
37 S 386 ALL^I 533 341
33 S 387 AMBC 1173 877
16 S 388 AXL 1266 393
25 B 389 ADC^A 1872 188
24 B 390 BBDC 438 481
38 S 391 ARE 1029 961
22 B 392 AFGE 1648 434
7 B 393 APO 377 23
6 B 394 BG 1996 100
28 S 395 BFK 1059 830
23 B 396 BAC^M 1092 435
13 B 397 AFGC 1530 474
21 B 398 ABC 1824 807
0 S 399 ARI 1354 313
8 B 400 BAC^K 260 211
8 S 401 AGM^E 1784 306
25 B 402 AAM^B 722 203
26 S 403 AJRD 742 778
16 B 404 ALV 1485 727
17 S 405 BKT 863 474
39 B 406 AEM 1114 143
18 B 407 ACHR 166 965
4 S 408 AMN 1941 190
29 S 409 BFH 1529 463
34 S 410 BIPH 770 645
28 B 411 BBWI 1447 219
21 S 412 BBY 683 281
13 S 413 BBVA 1133 547
26 B 414 BLCO 1192 966
28 B 415 AMT 853 708
22 S 416 ACR^D 1727 385
11 B 417 AUD 1504 79
3 S 418 AGM^D 1945 710
27 B 419 ALTG^A 367 370
29 S 420 ASPN 1067 516
11 S 421 AM 1957 246
10 S 422 AEFC 442 251
9 S 423 BC^A 295 359
30 B 424 AMN 1870 182
17 B 425 ABEV 203 892
2 B 426 BCE 229 823
15 S 427 AN 1997 987
38 B 428 ANET 861 768
10 B 429 BKKT 1165 279
2 S 430 BB 1909 582
35 B 431 AMWL 1263 489
17 S 432 ASGN 855 281
35 B 433 AFGB 518 956
31 S 434 ABR^F 1660 833
35 B 435 ARL 625 305
10 B 436 BIP 1012 776
30 B 437 AIZ 489 31
0 B 438 ASA 600 98
3 B 439 AQNA 240 62
16 S 440 A 292 234
32 B 441 BAP 1748 650
21 B 442 ABC 311 941
9 B 443 BEST 887 26
2 B 444 BH 628 515
19 S 445 BABA 1820 465
13 B 446 AJXA 549 787
26 S 447 BFAC 731 904
31 B 448 BIPC 451 452
19 B 449 ATH^C 1279 382
33 B 450 AIRC 340 702
26 S 451 ARGO 259 289
24 S 452 AEO 1047 768
32 S 453 BEP 1437 109
0 B 454 AIZ 199 615
35 B 455 AOS 684 198
5 S 456 BKKT 148 953
35 S 457 AJXA 1258 905
0 S 458 AQNB 838 707
36 S 459 BBAI 1656 371
14 B 460 AMPX 644 840
24 S 461 BIP 1104 91
15 S 462 BKDT 762 53
2 S 463 AIF 366 516
7 B 464 ASA 1665 365
32 B 465 AWR 1964 284
7 S 466 AHT^H 367 777
